Workbook

Sheet Frontend Tasks
A1: Task ID | B1: Module | C1: Task | D1: Details / Acceptance criteria | E1: SRS Ref | F1: Priority | G1: Status | H1: Done By | I1: Date Done | J1: Notes
A2: FE-001 | B2: 1. Setup & Foundation | C2: Initialise React project and folder structure | D2: Vite + React app with assets, components, pages, services, data, hooks, context, routes, utils folders. App runs with npm run dev. | E2: CON-01, NFR-MAIN-01 | F2: Must | G2: Done | H2: aminullah-01 | I2: 2026-09-22 | J2: Vite + React app initialised with modular folder structure. npm run dev and build verified.
A3: FE-002 | B3: 1. Setup & Foundation | C3: Configure ESLint, Prettier and pre-commit checks | D3: Lint and format scripts pass on a clean checkout; hook blocks commits that fail lint. | E3: NFR-MAIN-03 | F3: Should | G3: Done | H3: aminullah-01 | I3: 2026-09-25 | J3: Configured ESLint 9, Prettier, lint-staged, and Husky pre-commit hook. Verified pre-commit blocks lint failures and scripts pass.
A4: FE-003 | B4: 1. Setup & Foundation | C4: Environment configuration | D4: Create .env.example with API base URL and a mock/API switch. No secrets committed. | E4: NFR-MAIN-02, NFR-SEC-09 | F4: Must | G4: Done | H4: aminullah-01 | I4: 2026-09-25 | J4: Created .env.example and .env with VITE_API_BASE_URL and VITE_USE_MOCK_DATA switch. Verified .env is gitignored and src/utils/env.js works.
A5: FE-004 | B5: 1. Setup & Foundation | C5: Set up routing with full route map | D5: React Router routes for public, buyer, seller, admin and error pages exactly as in SRS 4.1.2. | E5: SRS 4.1.2 | F5: Must | G5: Done | H5: aminullah-01 | I5: 2026-09-27 | J5: Implemented React Router route map for all public, buyer, seller, admin and error routes matching SRS 4.1.2 with layout shells.
A6: FE-005 | B6: 1. Setup & Foundation | C6: Design tokens and global styles | D6: Colours, typography, spacing, breakpoints defined once; consistent across all roles. | E6: UI-02 | F6: Must | G6: Done | H6: aminullah-01 | I6: 2026-09-27 | J6: Defined design tokens in src/utils/tokens.js and CSS custom properties in src/index.css for colours, typography, 8px spacing, and 360-1920px breakpoints.
A7: FE-006 | B7: 1. Setup & Foundation | C7: Responsive layout shell | D7: Layout works from 360 px to 1920 px with no horizontal page scroll (breakpoints 360/768/1024/1280). | E7: NFR-COMP-02, UI-04 | F7: Must | G7: Done | H7: aminullah-01 | I7: 2026-09-27 | J7: Implemented responsive layout shells (MainLayout with hamburger drawer, DashboardLayout with off-canvas sidebar), table-responsive wrappers, and 360-1920px overflow protections.
A8: FE-007 | B8: 1. Setup & Foundation | C8: Formatting utilities (currency, dates) | D8: Prices show as ₦2,500 with unit; timestamps stored UTC, displayed Africa/Lagos. | E8: NFR-USAB-04, NFR-LOC-02 | F8: Must | G8: Done | H8: aminullah-01 | I8: 2026-09-27 | J8: Created formatters in src/utils/formatters.js: formatCurrency, formatPrice (₦2,500 / basket), formatDate/formatDateTime (Africa/Lagos WAT), and toUtcIso.
A9: FE-008 | B9: 1. Setup & Foundation | C9: UI strings/constants file | D9: User-facing text (incl. standard error messages) kept in one place so translation can be added later. | E9: NFR-LOC-01, ERR-01 | F9: Should | G9: Done
A10: FE-009 | B10: 1. Setup & Foundation | C10: API client wrapper | D10: Base URL, Authorization header, JSON envelope handling, normalised errors (401/403/404/409/422/429/5xx). | E10: IF-01 to IF-05 | F10: Must | G10: Done
A11: FE-010 | B11: 1. Setup & Foundation | C11: Service layer skeleton | D11: productService, categoryService, orderService, authService, sellerService, adminService; components never import mock data directly. | E11: CON-02 | F11: Must | G11: Done
A12: FE-011 | B12: 1. Setup & Foundation | C12: Mock data conforming to API schema | D12: Mock products, sellers, categories, orders match the API/OpenAPI field names and shapes. | E12: IF-06, NFR-MAIN-05 | F12: Must | G12: Done
A13: FE-012 | B13: 1. Setup & Foundation | C13: Mock/API switch | D13: One environment setting flips all services between mock data and the Laravel API with zero component changes. | E13: NFR-MAIN-02 | F13: Must | G13: Done
A14: FE-013 | B14: 1. Setup & Foundation | C14: Auth context | D14: Holds user, role and token; login, logout, session restore on refresh. | E14: AUTH-04, AUTH-05 | F14: Must | G14: Done
A15: FE-014 | B15: 1. Setup & Foundation | C15: Cart context with persistence | D15: Cart survives refresh and browser restart on the same device; storage calls wrapped in try/catch. | E15: CART-06 | F15: Must | G15: Done
A16: FE-015 | B16: 1. Setup & Foundation | C16: Route guards (role-based) | D16: Buyer, Seller and Admin routes blocked for other roles; unauthenticated users sent to login and back. | E16: AUTH-07 | F16: Must | G16: Done
A17: FE-016 | B17: 1. Setup & Foundation | C17: Error boundary and error pages | D17: Friendly 403, 404, 500 pages; session-expired prompt returns user to login and back. | E17: ERR-04 | F17: Should | G17: Done
A18: FE-017 | B18: 1. Setup & Foundation | C18: Loading, empty and error state components | D18: Reusable spinner/skeleton, empty state, and “Unable to load… Try again” with retry. | E18: MKT-10, ERR-01 | F18: Must | G18: Done
A19: FE-018 | B19: 1. Setup & Foundation | C19: Toast/notification component | D19: Success and error toasts used consistently across forms and actions. | E19: ERR-03 | F19: Should | G19: Done
A20: FE-019 | B20: 1. Setup & Foundation | C20: Test framework setup | D20: Vitest/Jest and React Testing Library configured; sample test runs in CI. | E20: NFR-MAIN-04 | F20: Should | G20: Done
... A32: FE-031 | B32: 2. Shared Components | C32: Category card/chip | D32: Used on homepage and filter panel; data-driven from API. | E32: MKT-08, MKT-09 | F32: Must | G32: Not Started
A33: FE-032 | B33: 2. Shared Components | C33: Seller card | D33: Business name, location, rating/summary, link to seller profile. | E33: MKT-01, MKT-07 | F33: Should | G33: Done | H33: aminullah-01 | I33: 2026-09-29 | J33: Implemented SellerCard in src/components/products/SellerCard.jsx: business name, location, rating or "No ratings yet", short description and product count, plus a 44px "View Seller" link to /sellers/:id. Data-driven from seller_profiles columns and hides unapproved sellers from public listings (MKT-04). 14 tests added; lint, format, full suite and build pass.
A34: FE-033 | B34: 2. Shared Components | C34: Search bar | D34: Keyword search with submit; used in navbar and hero. | E34: SRCH-01 | F34: Must | G34: Done | H34: aminullah-01 | I34: 2026-09-29 | J34: Implemented shared SearchBar in src/components/common/SearchBar.jsx: keyword field with submit, trimmed/encoded into ?search= on /products (SRCH-01, SRCH-06), URL-synced input, optional clear action and 44px touch targets. Refactored Navbar desktop and mobile drawer to use it (removed duplicate inline forms) and added .search-bar styles. 16 tests added; lint, format, full suite (239 tests) and build pass.
A35: FE-034 | B35: 2. Shared Components | C35: Filter panel | D35: Category, price range, availability, seller, location; collapsible on mobile. | E35: SRCH-02, SRCH-03 | F35: Must | G35: Done
A36: FE-035 | B36: 2. Shared Components | C36: Sort dropdown | D36: Price low→high, high→low, newest (popularity/rating when available). | E36: SRCH-04, SRCH-05 | F36: Must | G36: Done
A37: FE-036 | B37: 2. Shared Components | C37: Modal / confirm dialog | D37: Accessible dialog for delete, cancel and override confirmations. | E37: SEL-04, ORD-07 | F37: Must | G37: Done
A38: FE-037 | B38: 2. Shared Components | C38: Responsive data table | D38: Table that scrolls or turns into cards on tablets; used across dashboards. | E38: NFR-USAB-06 | F38: Must | G38: Done
A39: FE-038 | B39: 2. Shared Components | C39: Order status badge and timeline | D39: Colour-coded status badge; timeline of status history with timestamps. | E39: ORD-02, ORD-06 | F39: Must | G39: Done
A40: FE-039 | B40: 2. Shared Components | C40: Lazy image with placeholder | D40: Lazy-loads below the fold; default placeholder when image missing or fails. | E40: NFR-PERF-03, NFR-COMP-03, SEL-05 | F40: Must | G40: Done
A41: FE-040 | B41: 2. Shared Components | C41: Skeleton loaders | D41: Skeletons for product grid, tables and detail pages. | E41: MKT-10 | F41: Could | G41: Done
A42: FE-041 | B42: 3. Public Pages | C42: Home: hero section with search | D42: Headline, call to action and search box. | E42: MKT-01 | F42: Must | G42: Done
A43: FE-042 | B43: 3. Public Pages | C43: Home: featured products section | D43: Grid of featured/latest products from the service layer. | E43: MKT-01 | F43: Must | G43: Done
A44: FE-043 | B44: 3. Public Pages | C44: Home: categories section | D44: Category cards linking to filtered listing. | E44: MKT-01, MKT-08 | F44: Must | G44: Done
A45: FE-044 | B45: 3. Public Pages | C45: Home: featured sellers section | D45: Seller cards linking to seller profile. | E45: MKT-01 | F45: Should | G45: Done
A46: FE-045 | B46: 3. Public Pages | C46: Home: how it works, benefits and CTA sections | D46: Static content sections per source design; responsive. | E46: MKT-01 | F46: Must | G46: Done
... A126: FE-125 | B126: 10. Testing, Quality & Release | C126: README and developer documentation | D126: Setup, env variables, folder structure, mock/API switch, coding standards. | E126: NFR-MAIN-01 | F126: Should | G126: Not Started

Sheet Summary
A1: Vegetable Joint — Frontend Progress Summary
A2: All figures update automatically from the “Frontend Tasks” sheet (rows 2–500).
A4: Overall | B4: Count
A5: Total tasks | B5: =COUNTA('Frontend Tasks'!$A$2:$A$500) -> 125
A6: Done | B6: =COUNTIF('Frontend Tasks'!$G$2:$G$500,"Done") -> 0
A7: In Review | B7: =COUNTIF('Frontend Tasks'!$G$2:$G$500,"In Review") -> 0
A8: In Progress | B8: =COUNTIF('Frontend Tasks'!$G$2:$G$500,"In Progress") -> 0
A9: Blocked | B9: =COUNTIF('Frontend Tasks'!$G$2:$G$500,"Blocked") -> 0
A10: Not Started | B10: =COUNTIF('Frontend Tasks'!$G$2:$G$500,"Not Started") -> 125
A11: % complete | B11: =IF(B5=0,0,B6/B5) -> 0
A13: Module | B13: Total | C13: Done | D13: In Progress | E13: % Done
A14: 1. Setup & Foundation | B14: =COUNTIF('Frontend Tasks'!$B$2:$B$500,A14) -> 21 | C14: =COUNTIFS('Frontend Tasks'!$B$2:$B$500,A14,'Frontend Tasks'!$G$2:$G$500,"Done") -> 0 | D14: =COUNTIFS('Frontend Tasks'!$B$2:$B$500,A14,'Frontend Tasks'!$G$2:$G$500,"In Progress") -> 0 | E14: =IF(B14=0,0,C14/B14) -> 0
A15: 2. Shared Components | B15: =COUNTIF('Frontend Tasks'!$B$2:$B$500,A15) -> 19 | C15: =COUNTIFS('Frontend Tasks'!$B$2:$B$500,A15,'Frontend Tasks'!$G$2:$G$500,"Done") -> 0 | D15: =COUNTIFS('Frontend Tasks'!$B$2:$B$500,A15,'Frontend Tasks'!$G$2:$G$500,"In Progress") -> 0 | E15: =IF(B15=0,0,C15/B15) -> 0
A16: 3. Public Pages | B16: =COUNTIF('Frontend Tasks'!$B$2:$B$500,A16) -> 13 | C16: =COUNTIFS('Frontend Tasks'!$B$2:$B$500,A16,'Frontend Tasks'!$G$2:$G$500,"Done") -> 0 | D16: =COUNTIFS('Frontend Tasks'!$B$2:$B$500,A16,'Frontend Tasks'!$G$2:$G$500,"In Progress") -> 0 | E16: =IF(B16=0,0,C16/B16) -> 0
A17: 4. Cart | B17: =COUNTIF('Frontend Tasks'!$B$2:$B$500,A17) -> 8 | C17: =COUNTIFS('Frontend Tasks'!$B$2:$B$500,A17,'Frontend Tasks'!$G$2:$G$500,"Done") -> 0 | D17: =COUNTIFS('Frontend Tasks'!$B$2:$B$500,A17,'Frontend Tasks'!$G$2:$G$500,"In Progress") -> 0 | E17: =IF(B17=0,0,C17/B17) -> 0
A18: 5. Authentication & Account | B18: =COUNTIF('Frontend Tasks'!$B$2:$B$500,A18) -> 8 | C18: =COUNTIFS('Frontend Tasks'!$B$2:$B$500,A18,'Frontend Tasks'!$G$2:$G$500,"Done") -> 0 | D18: =COUNTIFS('Frontend Tasks'!$B$2:$B$500,A18,'Frontend Tasks'!$G$2:$G$500,"In Progress") -> 0 | E18: =IF(B18=0,0,C18/B18) -> 0
A19: 6. Checkout & Buyer Orders | B19: =COUNTIF('Frontend Tasks'!$B$2:$B$500,A19) -> 10 | C19: =COUNTIFS('Frontend Tasks'!$B$2:$B$500,A19,'Frontend Tasks'!$G$2:$G$500,"Done") -> 0 | D19: =COUNTIFS('Frontend Tasks'!$B$2:$B$500,A19,'Frontend Tasks'!$G$2:$G$500,"In Progress") -> 0 | E19: =IF(B19=0,0,C19/B19) -> 0
A20: 7. Seller Dashboard | B20: =COUNTIF('Frontend Tasks'!$B$2:$B$500,A20) -> 15 | C20: =COUNTIFS('Frontend Tasks'!$B$2:$B$500,A20,'Frontend Tasks'!$G$2:$G$500,"Done") -> 0 | D20: =COUNTIFS('Frontend Tasks'!$B$2:$B$500,A20,'Frontend Tasks'!$G$2:$G$500,"In Progress") -> 0 | E20: =IF(B20=0,0,C20/B20) -> 0
A21: 8. Admin Dashboard | B21: =COUNTIF('Frontend Tasks'!$B$2:$B$500,A21) -> 10 | C21: =COUNTIFS('Frontend Tasks'!$B$2:$B$500,A21,'Frontend Tasks'!$G$2:$G$500,"Done") -> 0 | D21: =COUNTIFS('Frontend Tasks'!$B$2:$B$500,A21,'Frontend Tasks'!$G$2:$G$500,"In Progress") -> 0 | E21: =IF(B21=0,0,C21/B21) -> 0
A22: 9. API Integration | B22: =COUNTIF('Frontend Tasks'!$B$2:$B$500,A22) -> 7 | C22: =COUNTIFS('Frontend Tasks'!$B$2:$B$500,A22,'Frontend Tasks'!$G$2:$G$500,"Done") -> 0 | D22: =COUNTIFS('Frontend Tasks'!$B$2:$B$500,A22,'Frontend Tasks'!$G$2:$G$500,"In Progress") -> 0 | E22: =IF(B22=0,0,C22/B22) -> 0
A23: 10. Testing, Quality & Release | B23: =COUNTIF('Frontend Tasks'!$B$2:$B$500,A23) -> 14 | C23: =COUNTIFS('Frontend Tasks'!$B$2:$B$500,A23,'Frontend Tasks'!$G$2:$G$500,"Done") -> 0 | D23: =COUNTIFS('Frontend Tasks'!$B$2:$B$500,A23,'Frontend Tasks'!$G$2:$G$500,"In Progress") -> 0 | E23: =IF(B23=0,0,C23/B23) -> 0
A24: Total | B24: =SUM(B14:B23) -> 125 | C24: =SUM(C14:C23) -> 0 | D24: =SUM(D14:D23) -> 0 | E24: =IF(B24=0,0,C24/B24) -> 0
A26: Priority | B26: Total | C26: Done | D26: In Progress | E26: % Done
A27: Must | B27: =COUNTIF('Frontend Tasks'!$F$2:$F$500,A27) -> 92 | C27: =COUNTIFS('Frontend Tasks'!$F$2:$F$500,A27,'Frontend Tasks'!$G$2:$G$500,"Done") -> 0 | D27: =COUNTIFS('Frontend Tasks'!$F$2:$F$500,A27,'Frontend Tasks'!$G$2:$G$500,"In Progress") -> 0 | E27: =IF(B27=0,0,C27/B27) -> 0
A28: Should | B28: =COUNTIF('Frontend Tasks'!$F$2:$F$500,A28) -> 30 | C28: =COUNTIFS('Frontend Tasks'!$F$2:$F$500,A28,'Frontend Tasks'!$G$2:$G$500,"Done") -> 0 | D28: =COUNTIFS('Frontend Tasks'!$F$2:$F$500,A28,'Frontend Tasks'!$G$2:$G$500,"In Progress") -> 0 | E28: =IF(B28=0,0,C28/B28) -> 0
A29: Could | B29: =COUNTIF('Frontend Tasks'!$F$2:$F$500,A29) -> 3 | C29: =COUNTIFS('Frontend Tasks'!$F$2:$F$500,A29,'Frontend Tasks'!$G$2:$G$500,"Done") -> 0 | D29: =COUNTIFS('Frontend Tasks'!$F$2:$F$500,A29,'Frontend Tasks'!$G$2:$G$500,"In Progress") -> 0 | E29: =IF(B29=0,0,C29/B29) -> 0
A32: Done by person
A33: Type each team member’s name exactly as used in the “Done By” column (yellow cells).
A34: Team member | B34: Tasks done
B35: =IF(A35="","",COUNTIFS('Frontend Tasks'!$H$2:$H$500,A35,'Frontend Tasks'!$G$2:$G$500,"Done"))
B36: =IF(A36="","",COUNTIFS('Frontend Tasks'!$H$2:$H$500,A36,'Frontend Tasks'!$G$2:$G$500,"Done"))
B37: =IF(A37="","",COUNTIFS('Frontend Tasks'!$H$2:$H$500,A37,'Frontend Tasks'!$G$2:$G$500,"Done"))
B38: =IF(A38="","",COUNTIFS('Frontend Tasks'!$H$2:$H$500,A38,'Frontend Tasks'!$G$2:$G$500,"Done"))
B39: =IF(A39="","",COUNTIFS('Frontend Tasks'!$H$2:$H$500,A39,'Frontend Tasks'!$G$2:$G$500,"Done"))
B40: =IF(A40="","",COUNTIFS('Frontend Tasks'!$H$2:$H$500,A40,'Frontend Tasks'!$G$2:$G$500,"Done"))
B41: =IF(A41="","",COUNTIFS('Frontend Tasks'!$H$2:$H$500,A41,'Frontend Tasks'!$G$2:$G$500,"Done"))
B42: =IF(A42="","",COUNTIFS('Frontend Tasks'!$H$2:$H$500,A42,'Frontend Tasks'!$G$2:$G$500,"Done"))
B43: =IF(A43="","",COUNTIFS('Frontend Tasks'!$H$2:$H$500,A43,'Frontend Tasks'!$G$2:$G$500,"Done"))
B44: =IF(A44="","",COUNTIFS('Frontend Tasks'!$H$2:$H$500,A44,'Frontend Tasks'!$G$2:$G$500,"Done"))
A45: Done but no name in “Done By” | B45: =COUNTIFS('Frontend Tasks'!$G$2:$G$500,"Done",'Frontend Tasks'!$H$2:$H$500,"") -> 0
...

Sheet How to Use
A1: How to use this tracker
A3: Purpose | B3: Tracks every frontend (React) task for Vegetable Joint, derived from SRS v1.0. Each task links to the SRS requirement(s) it satisfies.
A4: What you edit | B4: Only these columns: Status, Done By, Date Done, Notes. Task/Details/SRS Ref/Priority can be edited by the project lead if scope changes.
A5: Status values | B5: Not Started · In Progress · In Review · Done · Blocked (dropdown).
A6: Priority | B6: Must = required for Release 1.0. Should = target for 1.0. Could = may move later (as defined in SRS section 1.2).
A7: Done By | B7: Type the name of the person who completed the task (e.g. “Amaka O.”). Use the same spelling every time so the Summary sheet can count it.
A8: Date Done | B8: Enter the date the task was completed in yyyy-mm-dd format (e.g. 2026-09-25).
A9: Example (not a real entry) | B9: Task FE-014 “Cart context with persistence” → Status: Done · Done By: Amaka O. · Date Done: 2026-09-25 · Notes: Tested on refresh and browser restart.
A10: Colour cues | B10: Green = Done, amber = In Progress, blue = In Review, red = Blocked. A red “Done By” cell means the task is Done but nobody is named.
A11: Adding tasks | B11: Insert new rows inside the table (before the last row) and copy formatting from a row above; Summary formulas cover rows 2–500. Use the next free Task ID.
A12: Starting status | B12: All tasks start as “Not Started”. The concept document does not record what is already built (a React prototype with mock data exists), so please update Status for work already completed.
A13: Assumptions | B13: Priorities and SRS references come from SRS v1.0. Estimates and assignees are intentionally left out; add columns if your team wants them.
A14: Use in Google Sheets | B14: Google Drive → New → File upload → open this file with Google Sheets (or File → Import). Dropdowns, filters and colours carry over.
